Traceback (most recent call last):
  File "/home/timothyprojectinfo/.local/lib/python3.9/site-packages/jupyter_cache/executors/utils.py", line 58, in single_nb_execution
    executenb(
  File "/home/timothyprojectinfo/.local/lib/python3.9/site-packages/nbclient/client.py", line 1305, in execute
    return NotebookClient(nb=nb, resources=resources, km=km, **kwargs).execute()
  File "/usr/local/lib/python3.9/dist-packages/jupyter_core/utils/__init__.py", line 166, in wrapped
    return loop.run_until_complete(inner)
  File "/usr/lib/python3.9/asyncio/base_events.py", line 642, in run_until_complete
    return future.result()
  File "/home/timothyprojectinfo/.local/lib/python3.9/site-packages/nbclient/client.py", line 705, in async_execute
    await self.async_execute_cell(
  File "/home/timothyprojectinfo/.local/lib/python3.9/site-packages/nbclient/client.py", line 1058, in async_execute_cell
    await self._check_raise_for_error(cell, cell_index, exec_reply)
  File "/home/timothyprojectinfo/.local/lib/python3.9/site-packages/nbclient/client.py", line 914, in _check_raise_for_error
    raise CellExecutionError.from_cell_and_msg(cell, exec_reply_content)
nbclient.exceptions.CellExecutionError: An error occurred while executing the following cell:
------------------
docs = text_df.text
count_vectorizer = CountVectorizer()
count_vectorizer.fit(docs) 
len(count_vectorizer.vocabulary_)
------------------


[0;31m---------------------------------------------------------------------------[0m
[0;31mNameError[0m                                 Traceback (most recent call last)
Cell [0;32mIn[1], line 1[0m
[0;32m----> 1[0m docs [38;5;241m=[39m [43mtext_df[49m[38;5;241m.[39mtext
[1;32m      2[0m count_vectorizer [38;5;241m=[39m CountVectorizer()
[1;32m      3[0m count_vectorizer[38;5;241m.[39mfit(docs) 

[0;31mNameError[0m: name 'text_df' is not defined

