Traceback (most recent call last):
  File "/home/timothyproject/anaconda3/lib/python3.8/site-packages/jupyter_cache/executors/utils.py", line 58, in single_nb_execution
    executenb(
  File "/home/timothyproject/anaconda3/lib/python3.8/site-packages/nbclient/client.py", line 1112, in execute
    return NotebookClient(nb=nb, resources=resources, km=km, **kwargs).execute()
  File "/home/timothyproject/anaconda3/lib/python3.8/site-packages/nbclient/util.py", line 74, in wrapped
    return just_run(coro(*args, **kwargs))
  File "/home/timothyproject/anaconda3/lib/python3.8/site-packages/nbclient/util.py", line 53, in just_run
    return loop.run_until_complete(coro)
  File "/home/timothyproject/anaconda3/lib/python3.8/asyncio/base_events.py", line 616, in run_until_complete
    return future.result()
  File "/home/timothyproject/anaconda3/lib/python3.8/site-packages/nbclient/client.py", line 553, in async_execute
    await self.async_execute_cell(
  File "/home/timothyproject/anaconda3/lib/python3.8/site-packages/nbclient/client.py", line 857, in async_execute_cell
    self._check_raise_for_error(cell, exec_reply)
  File "/home/timothyproject/anaconda3/lib/python3.8/site-packages/nbclient/client.py", line 760, in _check_raise_for_error
    raise CellExecutionError.from_cell_and_msg(cell, exec_reply_content)
nbclient.exceptions.CellExecutionError: An error occurred while executing the following cell:
------------------
docs = text_df.embedding.tolist()
scaler = preprocessing.MinMaxScaler().fit(docs)
X = scaler.transform(docs)
y = text_df.sdg
X_train, X_test, y_train, y_test = \
    train_test_split(X, y, test_size=0.33, random_state=7)
ridge_clf = RidgeClassifier(tol=1e-2, solver="sparse_cg")
ridge_clf = ridge_clf.fit(X_train, y_train)
y_pred = ridge_clf.predict(X_test)
print(metrics.classification_report(y_test,y_pred, digits = 4))
ConfusionMatrixDisplay.from_predictions(y_test, y_pred)
------------------

[0;31m---------------------------------------------------------------------------[0m
[0;31mNameError[0m                                 Traceback (most recent call last)
[0;32m<ipython-input-1-3f2753b9715f>[0m in [0;36m<module>[0;34m[0m
[0;32m----> 1[0;31m [0mdocs[0m [0;34m=[0m [0mtext_df[0m[0;34m.[0m[0membedding[0m[0;34m.[0m[0mtolist[0m[0;34m([0m[0;34m)[0m[0;34m[0m[0;34m[0m[0m
[0m[1;32m      2[0m [0mscaler[0m [0;34m=[0m [0mpreprocessing[0m[0;34m.[0m[0mMinMaxScaler[0m[0;34m([0m[0;34m)[0m[0;34m.[0m[0mfit[0m[0;34m([0m[0mdocs[0m[0;34m)[0m[0;34m[0m[0;34m[0m[0m
[1;32m      3[0m [0mX[0m [0;34m=[0m [0mscaler[0m[0;34m.[0m[0mtransform[0m[0;34m([0m[0mdocs[0m[0;34m)[0m[0;34m[0m[0;34m[0m[0m
[1;32m      4[0m [0my[0m [0;34m=[0m [0mtext_df[0m[0;34m.[0m[0msdg[0m[0;34m[0m[0;34m[0m[0m
[1;32m      5[0m [0mX_train[0m[0;34m,[0m [0mX_test[0m[0;34m,[0m [0my_train[0m[0;34m,[0m [0my_test[0m [0;34m=[0m[0;31m [0m[0;31m\[0m[0;34m[0m[0;34m[0m[0m

[0;31mNameError[0m: name 'text_df' is not defined
NameError: name 'text_df' is not defined

